{"ec97ad7255d877589fecdcb284a81372":{"statistic":{"failed":0,"broken":0,"skipped":0,"passed":1,"unknown":0,"total":1},"items":[{"uid":"c2ff8b424c2766c5","status":"passed","time":{"start":1718382528636,"stop":1718382544414,"duration":15778}}]},"5e2c41a9cdbbf42bd4a11f3499915bb8":{"statistic":{"failed":0,"broken":0,"skipped":0,"passed":1,"unknown":0,"total":1},"items":[{"uid":"2da4c2c578f0904c","status":"passed","time":{"start":1718382513378,"stop":1718382525397,"duration":12019}}]},"839ec35416587875e619a24acbd03e11":{"statistic":{"failed":0,"broken":0,"skipped":0,"passed":0,"unknown":1,"total":1},"items":[{"uid":"e6a157488d95848e","status":"unknown","time":{"start":1718382513378,"stop":0,"duration":-1718382513378}}]},"a2c050297370f0665da5be5de3b1dc5a":{"statistic":{"failed":0,"broken":1,"skipped":0,"passed":0,"unknown":0,"total":1},"items":[{"uid":"2898f7c10bed4339","status":"broken","statusDetails":"The following error originated from your application code, not from Cypress.\n                \n                  > Cypress detected that you returned a promise from a command while also invoking one or more cy commands in that promise.\n                \n                The command that returned the promise was:\n                \n                  > `cy.click()`\n                \n                The cy command you invoked inside the promise was:\n                \n                  > `cy.log()`\n                \n                Because Cypress commands are already promise-like, you don't need to wrap them or return your own promise.\n                \n                Cypress will resolve your command with whatever the final Cypress command yields.\n                \n                The reason this is an error instead of a warning is because Cypress internally queues commands serially whereas Promises execute as soon as they are invoked. Attempting to reconcile this would prevent Cypress from ever resolving.\n                \n                When Cypress detects uncaught errors originating from your application it will automatically fail the current test.\n                \n                This behavior is configurable, and you can choose to turn this off by listening to the `uncaught:exception` event.\n                \n                https://on.cypress.io/uncaught-exception-from-application\n                \n                https://on.cypress.io/returning-promise-and-commands-in-another-command","time":{"start":1718382544444,"stop":1718382550067,"duration":5623}}]},"b7e5ddac37ed0d87a2b7abc0599b707d":{"statistic":{"failed":0,"broken":1,"skipped":0,"passed":0,"unknown":0,"total":1},"items":[{"uid":"6fb447febbf33a48","status":"broken","statusDetails":"Order ID does not exist in Cypress environment","time":{"start":1718382509214,"stop":1718382509888,"duration":674}}]}}